Workbook

Sheet Tarifario
A1: Segmento Copa | B1: Concessionaria | C1: Preço da Concessionaria é: | D1: Classe | E1: UF | F1: Concessionária | G1: Segmento | H1: Faixa Mín (m3) | I1: Faixa Máx (m3) | J1: Tarifa (R$/m³) | K1: Termo Fixo (R$) | L1: dt_delib | M1: PIS/Cofins | N1: ICMS | O1: Ordem | P1: Tabela | Q1: Tarifa em cascata? | R1: Fonte | S1: Periodo de renovação
A2: CONDOMINIOS | B2: SP (Comgás) | C2: com pis/cofins e sem icms | D2: 1 | E2: SP | F2: COMGÁS | G2: Residencial - Medição Coletiva | H2: 0 | I2: 500 | J2: 7.732893 | K2: 78.14 | L2: 46182 | M2: 0.089 | N2: =_xlfn.XLOOKUP(E2,ICMS!C:C,ICMS!D:D) -> 0.15 | O2: 1 | Q2: Não | R2: https://www.comgas.com.br/sobre-sua-conta/tarifas | S2: março, junho, setembro, dezembro
A3: CONDOMINIOS | B3: SP (Comgás) | C3: com pis/cofins e sem icms | D3: 2 | E3: SP | F3: COMGÁS | G3: Residencial - Medição Coletiva | H3: =I2+0.01 -> 500.01 | I3: 2000 | J3: 7.51779 | K3: 186.85 | L3: 46182 | M3: 0.089 | N3: =_xlfn.XLOOKUP(E3,ICMS!C:C,ICMS!D:D) -> 0.15 | O3: =1+O2 -> 2 | Q3: Não | R3: https://www.comgas.com.br/sobre-sua-conta/tarifas | S3: março, junho, setembro, dezembro
A4: CONDOMINIOS | B4: SP (Comgás) | C4: com pis/cofins e sem icms | D4: 3 | E4: SP | F4: COMGÁS | G4: Residencial - Medição Coletiva | H4: =I3+0.01 -> 2000.01 | I4: 99999999999 | J4: 7.248912 | K4: 730.35 | L4: 46182 | M4: 0.089 | N4: =_xlfn.XLOOKUP(E4,ICMS!C:C,ICMS!D:D) -> 0.15 | O4: =1+O3 -> 3 | Q4: Não | R4: https://www.comgas.com.br/sobre-sua-conta/tarifas | S4: março, junho, setembro, dezembro
A5: COMERCIAL E SERVIÇOS | B5: SP (Comgás) | C5: com pis/cofins e sem icms | D5: 1 | E5: SP | F5: COMGÁS | G5: Comercial | H5: 0 | I5: 150 | J5: 7.36581 | K5: 53.29 | L5: 46182 | M5: 0.089 | N5: =_xlfn.XLOOKUP(E5,ICMS!C:C,ICMS!D:D) -> 0.15 | O5: =1+O4 -> 4 | Q5: Não | R5: https://www.comgas.com.br/sobre-sua-conta/tarifas | S5: março, junho, setembro, dezembro
A6: COMERCIAL E SERVIÇOS | B6: SP (Comgás) | C6: com pis/cofins e sem icms | D6: 2 | E6: SP | F6: COMGÁS | G6: Comercial | H6: =I5+0.01 -> 150.01 | I6: 500 | J6: 6.929245 | K6: 119.47 | L6: 46182 | M6: 0.089 | N6: =_xlfn.XLOOKUP(E6,ICMS!C:C,ICMS!D:D) -> 0.15 | O6: =1+O5 -> 5 | Q6: Não | R6: https://www.comgas.com.br/sobre-sua-conta/tarifas | S6: março, junho, setembro, dezembro
A7: COMERCIAL E SERVIÇOS | B7: SP (Comgás) | C7: com pis/cofins e sem icms | D7: 3 | E7: SP | F7: COMGÁS | G7: Comercial | H7: =I6+0.01 -> 500.01 | I7: 3500 | J7: 6.293442 | K7: 440.78 | L7: 46182 | M7: 0.089 | N7: =_xlfn.XLOOKUP(E7,ICMS!C:C,ICMS!D:D) -> 0.15 | O7: =1+O6 -> 6 | Q7: Não | R7: https://www.comgas.com.br/sobre-sua-conta/tarifas | S7: março, junho, setembro, dezembro
A8: COMERCIAL E SERVIÇOS | B8: SP (Comgás) | C8: com pis/cofins e sem icms | D8: 4 | E8: SP | F8: COMGÁS | G8: Comercial | H8: =I7+0.01 -> 3500.01 | I8: 50000 | J8: 5.002828 | K8: 5006.35 | L8: 46182 | M8: 0.089 | N8: =_xlfn.XLOOKUP(E8,ICMS!C:C,ICMS!D:D) -> 0.15 | O8: =1+O7 -> 7 | Q8: Não | R8: https://www.comgas.com.br/sobre-sua-conta/tarifas | S8: março, junho, setembro, dezembro
A9: COMERCIAL E SERVIÇOS | B9: SP (Comgás) | C9: com pis/cofins e sem icms | D9: 5 | E9: SP | F9: COMGÁS | G9: Comercial | H9: =I8+0.01 -> 50000.01 | I9: 99999999999 | J9: 4.787725 | K9: 15876.35 | L9: 46182 | M9: 0.089 | N9: =_xlfn.XLOOKUP(E9,ICMS!C:C,ICMS!D:D) -> 0.15 | O9: =1+O8 -> 8 | Q9: Não | R9: https://www.comgas.com.br/sobre-sua-conta/tarifas | S9: março, junho, setembro, dezembro
A10: INDUSTRIAL | B10: SP (Comgás) | C10: com pis/cofins e sem icms | D10: 1 | E10: SP | F10: COMGÁS | G10: Industrial e Interruptível | H10: 0 | I10: 50000 | J10: 4.149025 | K10: 299.94 | L10: 46182 | M10: 0.089 | N10: =_xlfn.XLOOKUP(E10,ICMS!C:C,ICMS!D:D) -> 0.15 | O10: =1+O9 -> 9 | Q10: Não | R10: https://www.comgas.com.br/sobre-sua-conta/tarifas | S10: março, junho, setembro, dezembro
A11: INDUSTRIAL | B11: SP (Comgás) | C11: com pis/cofins e sem icms | D11: 2 | E11: SP | F11: COMGÁS | G11: Industrial e Interruptível | H11: =I10+0.01 -> 50000.01 | I11: 300000 | J11: 3.243632 | K11: 45569.61 | L11: 46182 | M11: 0.089 | N11: =_xlfn.XLOOKUP(E11,ICMS!C:C,ICMS!D:D) -> 0.15 | O11: =1+O10 -> 10 | Q11: Não | R11: https://www.comgas.com.br/sobre-sua-conta/tarifas | S11: março, junho, setembro, dezembro
A12: INDUSTRIAL | B12: SP (Comgás) | C12: com pis/cofins e sem icms | D12: 3 | E12: SP | F12: COMGÁS | G12: Industrial e Interruptível | H12: =I11+0.01 -> 300000.01 | I12: 500000 | J12: 3.139563 | K12: 76814.74 | L12: 46182 | M12: 0.089 | N12: =_xlfn.XLOOKUP(E12,ICMS!C:C,ICMS!D:D) -> 0.15 | O12: =1+O11 -> 11 | Q12: Não | R12: https://www.comgas.com.br/sobre-sua-conta/tarifas | S12: março, junho, setembro, dezembro
A13: INDUSTRIAL | B13: SP (Comgás) | C13: com pis/cofins e sem icms | D13: 4 | E13: SP | F13: COMGÁS | G13: Industrial e Interruptível | H13: =I12+0.01 -> 500000.01 | I13: 1000000 | J13: 3.085472 | K13: 104696.61 | L13: 46182 | M13: 0.089 | N13: =_xlfn.XLOOKUP(E13,ICMS!C:C,ICMS!D:D) -> 0.15 | O13: =1+O12 -> 12 | Q13: Não | R13: https://www.comgas.com.br/sobre-sua-conta/tarifas | S13: março, junho, setembro, dezembro
A14: INDUSTRIAL | B14: SP (Comgás) | C14: com pis/cofins e sem icms | D14: 5 | E14: SP | F14: COMGÁS | G14: Industrial e Interruptível | H14: =I13+0.01 -> 1000000 | I14: 2000000 | J14: 3.04572 | K14: 145676.98 | L14: 46182 | M14: 0.089 | N14: =_xlfn.XLOOKUP(E14,ICMS!C:C,ICMS!D:D) -> 0.15 | O14: =1+O13 -> 13 | Q14: Não | R14: https://www.comgas.com.br/sobre-sua-conta/tarifas | S14: março, junho, setembro, dezembro
A15: INDUSTRIAL | B15: SP (Comgás) | C15: com pis/cofins e sem icms | D15: 6 | E15: SP | F15: COMGÁS | G15: Industrial e Interruptível | H15: =I14+0.01 -> 2000000 | I15: 99999999999 | J15: 2.995953 | K15: 248290.96 | L15: 46182 | M15: 0.089 | N15: =_xlfn.XLOOKUP(E15,ICMS!C:C,ICMS!D:D) -> 0.15 | O15: =1+O14 -> 14 | Q15: Não | R15: https://www.comgas.com.br/sobre-sua-conta/tarifas | S15: março, junho, setembro, dezembro
A16: REVENDA | B16: SP (Comgás) | C16: com pis/cofins e sem icms | D16: 1 | E16: SP | F16: COMGÁS | G16: Residencial | H16: 0 | I16: 1 | J16: 2.337387 | K16: 10.54 | L16: 46182 | M16: 0.089 | N16: =_xlfn.XLOOKUP(E16,ICMS!C:C,ICMS!D:D) -> 0.15 | O16: =1+O15 -> 15 | Q16: Não | R16: https://www.comgas.com.br/sobre-sua-conta/tarifas | S16: março, junho, setembro, dezembro
A17: REVENDA | B17: SP (Comgás) | C17: com pis/cofins e sem icms | D17: 2 | E17: SP | F17: COMGÁS | G17: Residencial | H17: =I16+0.01 -> 1.01 | I17: 3 | J17: 11.502461 | K17: 1.38 | L17: 46182 | M17: 0.089 | N17: =_xlfn.XLOOKUP(E17,ICMS!C:C,ICMS!D:D) -> 0.15 | O17: =1+O16 -> 16 | Q17: Não | R17: https://www.comgas.com.br/sobre-sua-conta/tarifas | S17: março, junho, setembro, dezembro
A18: REVENDA | B18: SP (Comgás) | C18: com pis/cofins e sem icms | D18: 3 | E18: SP | F18: COMGÁS | G18: Residencial | H18: =I17+0.01 -> 3.01 | I18: 7 | J18: 4.865142 | K18: 21.3 | L18: 46182 | M18: 0.089 | N18: =_xlfn.XLOOKUP(E18,ICMS!C:C,ICMS!D:D) -> 0.15 | O18: =1+O17 -> 17 | Q18: Não | R18: https://www.comgas.com.br/sobre-sua-conta/tarifas | S18: março, junho, setembro, dezembro
A19: REVENDA | B19: SP (Comgás) | C19: com pis/cofins e sem icms | D19: 4 | E19: SP | F19: COMGÁS | G19: Residencial | H19: =I18+0.01 -> 7.01 | I19: 14 | J19: 8.566749 | K19: -4.63 | L19: 46182 | M19: 0.089 | N19: =_xlfn.XLOOKUP(E19,ICMS!C:C,ICMS!D:D) -> 0.15 | O19: =1+O18 -> 18 | Q19: Não | R19: https://www.comgas.com.br/sobre-sua-conta/tarifas | S19: março, junho, setembro, dezembro
A20: REVENDA | B20: SP (Comgás) | C20: com pis/cofins e sem icms | D20: 5 | E20: SP | F20: COMGÁS | G20: Residencial | H20: =I19+0.01 -> 14.01 | I20: 99999999999 | J20: 10.052583 | K20: -25.43 | L20: 46182 | M20: 0.089 | N20: =_xlfn.XLOOKUP(E20,ICMS!C:C,ICMS!D:D) -> 0.15 | O20: =1+O19 -> 19 | Q20: Não | R20: https://www.comgas.com.br/sobre-sua-conta/tarifas | S20: março, junho, setembro, dezembro
A21: REVENDA | B21: SP (Naturgy) | C21: com pis/cofins e sem icms | D21: 1 | E21: SP | F21: NATURGY | G21: Residencial | H21: 0 | I21: 1 | J21: 1.8863 | K21: 25.29 | L21: 46173 | M21: 0.09 | N21: =_xlfn.XLOOKUP(E21,ICMS!C:C,ICMS!D:D) -> 0.15 | O21: =1+O20 -> 20 | Q21: Não | R21: https://www.naturgy.com.br/atendimento/tarifas/tarifa_sao_paulo | S21: fevereiro, maio,agosto, novembro
A22: REVENDA | B22: SP (Naturgy) | C22: com pis/cofins e sem icms | D22: 2 | E22: SP | F22: NATURGY | G22: Residencial | H22: =I21+0.01 -> 1.01 | I22: 7 | J22: 6.6179 | K22: 19.77 | L22: 46173 | M22: 0.09 | N22: =_xlfn.XLOOKUP(E22,ICMS!C:C,ICMS!D:D) -> 0.15 | O22: =1+O21 -> 21 | Q22: Não | R22: https://www.naturgy.com.br/atendimento/tarifas/tarifa_sao_paulo | S22: fevereiro, maio,agosto, novembro
A23: REVENDA | B23: SP (Naturgy) | C23: com pis/cofins e sem icms | D23: 3 | E23: SP | F23: NATURGY | G23: Residencial | H23: =I22+0.01 -> 7.01 | I23: 16 | J23: 6.425 | K23: 21.32 | L23: 46173 | M23: 0.09 | N23: =_xlfn.XLOOKUP(E23,ICMS!C:C,ICMS!D:D) -> 0.15 | O23: =1+O22 -> 22 | Q23: Não | R23: https://www.naturgy.com.br/atendimento/tarifas/tarifa_sao_paulo | S23: fevereiro, maio,agosto, novembro
A24: REVENDA | B24: SP (Naturgy) | C24: com pis/cofins e sem icms | D24: 4 | E24: SP | F24: NATURGY | G24: Residencial | H24: =I23+0.01 -> 16.01 | I24: 41 | J24: 6.2942 | K24: 23.75 | L24: 46173 | M24: 0.09 | N24: =_xlfn.XLOOKUP(E24,ICMS!C:C,ICMS!D:D) -> 0.15 | O24: =1+O23 -> 23 | Q24: Não | R24: https://www.naturgy.com.br/atendimento/tarifas/tarifa_sao_paulo | S24: fevereiro, maio,agosto, novembro
A25: REVENDA | B25: SP (Naturgy) | C25: com pis/cofins e sem icms | D25: 5 | E25: SP | F25: NATURGY | G25: Residencial | H25: =I24+0.01 -> 41.01 | I25: 99999999999 | J25: 6.2762 | K25: 24.53 | L25: 46173 | M25: 0.09 | N25: =_xlfn.XLOOKUP(E25,ICMS!C:C,ICMS!D:D) -> 0.15 | O25: =1+O24 -> 24 | Q25: Não | R25: https://www.naturgy.com.br/atendimento/tarifas/tarifa_sao_paulo | S25: fevereiro, maio,agosto, novembro
A26: CONDOMINIOS | B26: SP (Naturgy) | C26: com pis/cofins e sem icms | D26: 1 | E26: SP | F26: NATURGY | G26: Residencial - Medição Coletiva | H26: 0 | I26: 100 | J26: 6.8116 | K26: 32.88 | L26: 46173 | M26: 0.09 | N26: =_xlfn.XLOOKUP(E26,ICMS!C:C,ICMS!D:D) -> 0.15 | O26: =1+O25 -> 25 | Q26: Não | R26: https://www.naturgy.com.br/atendimento/tarifas/tarifa_sao_paulo | S26: fevereiro, maio,agosto, novembro
A27: CONDOMINIOS | B27: SP (Naturgy) | C27: com pis/cofins e sem icms | D27: 2 | E27: SP | F27: NATURGY | G27: Residencial - Medição Coletiva | H27: =I26+0.01 -> 100.01 | I27: 300 | J27: 6.4161 | K27: 49.32 | L27: 46173 | M27: 0.09 | N27: =_xlfn.XLOOKUP(E27,ICMS!C:C,ICMS!D:D) -> 0.15 | O27: =1+O26 -> 26 | Q27: Não | R27: https://www.naturgy.com.br/atendimento/tarifas/tarifa_sao_paulo | S27: fevereiro, maio,agosto, novembro
A28: CONDOMINIOS | B28: SP (Naturgy) | C28: com pis/cofins e sem icms | D28: 3 | E28: SP | F28: NATURGY | G28: Residencial - Medição Coletiva | H28: =I27+0.01 -> 300.01 | I28: 99999999999 | J28: 6.2162 | K28: 98.64 | L28: 46173 | M28: 0.09 | N28: =_xlfn.XLOOKUP(E28,ICMS!C:C,ICMS!D:D) -> 0.15 | O28: =1+O27 -> 27 | Q28: Não | R28: https://www.naturgy.com.br/atendimento/tarifas/tarifa_sao_paulo | S28: fevereiro, maio,agosto, novembro
A29: COMERCIAL E SERVIÇOS | B29: SP (Naturgy) | C29: com pis/cofins e sem icms | D29: 1 | E29: SP | F29: NATURGY | G29: Comercial | H29: 0 | I29: 150 | J29: 7.0357 | K29: 67.23 | L29: 46173 | M29: 0.09 | N29: =_xlfn.XLOOKUP(E29,ICMS!C:C,ICMS!D:D) -> 0.15 | O29: =1+O28 -> 28 | Q29: Não | R29: https://www.naturgy.com.br/atendimento/tarifas/tarifa_sao_paulo | S29: fevereiro, maio,agosto, novembro
A30: COMERCIAL E SERVIÇOS | B30: SP (Naturgy) | C30: com pis/cofins e sem icms | D30: 2 | E30: SP | F30: NATURGY | G30: Comercial | H30: =I29+0.01 -> 150.01 | I30: 300 | J30: 6.3634 | K30: 105.06 | L30: 46173 | M30: 0.09 | N30: =_xlfn.XLOOKUP(E30,ICMS!C:C,ICMS!D:D) -> 0.15 | O30: =1+O29 -> 29 | Q30: Não | R30: https://www.naturgy.com.br/atendimento/tarifas/tarifa_sao_paulo | S30: fevereiro, maio,agosto, novembro
A31: COMERCIAL E SERVIÇOS | B31: SP (Naturgy) | C31: com pis/cofins e sem icms | D31: 3 | E31: SP | F31: NATURGY | G31: Comercial | H31: =I30+0.01 -> 300.01 | I31: 1000 | J31: 5.6249 | K31: 450.46 | L31: 46173 | M31: 0.09 | N31: =_xlfn.XLOOKUP(E31,ICMS!C:C,ICMS!D:D) -> 0.15 | O31: =1+O30 -> 30 | Q31: Não | R31: https://www.naturgy.com.br/atendimento/tarifas/tarifa_sao_paulo | S31: fevereiro, maio,agosto, novembro
A32: COMERCIAL E SERVIÇOS | B32: SP (Naturgy) | C32: com pis/cofins e sem icms | D32: 4 | E32: SP | F32: NATURGY | G32: Comercial | H32: =I31+0.01 -> 1000.01 | I32: 3000 | J32: 4.5146 | K32: 1801.81 | L32: 46173 | M32: 0.09 | N32: =_xlfn.XLOOKUP(E32,ICMS!C:C,ICMS!D:D) -> 0.15 | O32: =1+O31 -> 31 | Q32: Não | R32: https://www.naturgy.com.br/atendimento/tarifas/tarifa_sao_paulo | S32: fevereiro, maio,agosto, novembro
A33: COMERCIAL E SERVIÇOS | B33: SP (Naturgy) | C33: com pis/cofins e sem icms | D33: 5 | E33: SP | F33: NATURGY | G33: Comercial | H33: =I31+0.01 -> 1000.01 | I33: 99999999999 | J33: 4.2047 | K33: 4370.43 | L33: 46173 | M33: 0.09 | N33: =_xlfn.XLOOKUP(E33,ICMS!C:C,ICMS!D:D) -> 0.15 | O33: =1+O32 -> 32 | Q33: Não | R33: https://www.naturgy.com.br/atendimento/tarifas/tarifa_sao_paulo | S33: fevereiro, maio,agosto, novembro
A34: INDUSTRIAL | B34: SP (Naturgy) | C34: com pis/cofins e sem icms | D34: 1 | E34: SP | F34: NATURGY | G34: Industrial | H34: 0 | I34: 5000 | J34: 6.3259 | K34: 573.69 | L34: 46173 | M34: 0.09 | N34: =_xlfn.XLOOKUP(E34,ICMS!C:C,ICMS!D:D) -> 0.15 | O34: =1+O33 -> 33 | Q34: Não | R34: https://www.naturgy.com.br/atendimento/tarifas/tarifa_sao_paulo | S34: fevereiro, maio,agosto, novembro
A35: INDUSTRIAL | B35: SP (Naturgy) | C35: com pis/cofins e sem icms | D35: 2 | E35: SP | F35: NATURGY | G35: Industrial | H35: =I34+0.01 -> 5000.01 | I35: 50000 | J35: 4.2829 | K35: 11476.17 | L35: 46173 | M35: 0.09 | N35: =_xlfn.XLOOKUP(E35,ICMS!C:C,ICMS!D:D) -> 0.15 | O35: =1+O34 -> 34 | Q35: Não | R35: https://www.naturgy.com.br/atendimento/tarifas/tarifa_sao_paulo | S35: fevereiro, maio,agosto, novembro
A36: INDUSTRIAL | B36: SP (Naturgy) | C36: com pis/cofins e sem icms | D36: 3 | E36: SP | F36: NATURGY | G36: Industrial | H36: =I35+0.01 -> 50000.01 | I36: 300000 | J36: 3.3745 | K36: 53176.14 | L36: 46173 | M36: 0.09 | N36: =_xlfn.XLOOKUP(E36,ICMS!C:C,ICMS!D:D) -> 0.15 | O36: =1+O35 -> 35 | Q36: Não | R36: https://www.naturgy.com.br/atendimento/tarifas/tarifa_sao_paulo | S36: fevereiro, maio,agosto, novembro
A37: INDUSTRIAL | B37: SP (Naturgy) | C37: com pis/cofins e sem icms | D37: 4 | E37: SP | F37: NATURGY | G37: Industrial | H37: =I36+0.01 -> 300000.01 | I37: 500000 | J37: 3.1407 | K37: 138253.36 | L37: 46173 | M37: 0.09 | N37: =_xlfn.XLOOKUP(E37,ICMS!C:C,ICMS!D:D) -> 0.15 | O37: =1+O36 -> 36 | Q37: Não | R37: https://www.naturgy.com.br/atendimento/tarifas/tarifa_sao_paulo | S37: fevereiro, maio,agosto, novembro
A38: INDUSTRIAL | B38: SP (Naturgy) | C38: com pis/cofins e sem icms | D38: 5 | E38: SP | F38: NATURGY | G38: Industrial | H38: =I37+0.01 -> 500000.01 | I38: 2000000 | J38: 2.9094 | K38: 152827.11 | L38: 46173 | M38: 0.09 | N38: =_xlfn.XLOOKUP(E38,ICMS!C:C,ICMS!D:D) -> 0.15 | O38: =1+O37 -> 37 | Q38: Não | R38: https://www.naturgy.com.br/atendimento/tarifas/tarifa_sao_paulo | S38: fevereiro, maio,agosto, novembro
A39: INDUSTRIAL | B39: SP (Naturgy) | C39: com pis/cofins e sem icms | D39: 6 | E39: SP | F39: NATURGY | G39: Industrial | H39: =I38+0.01 -> 2000000 | I39: 5000000 | J39: 2.8248 | K39: 164528.82 | L39: 46173 | M39: 0.09 | N39: =_xlfn.XLOOKUP(E39,ICMS!C:C,ICMS!D:D) -> 0.15 | O39: =1+O38 -> 38 | Q39: Não | R39: https://www.naturgy.com.br/atendimento/tarifas/tarifa_sao_paulo | S39: fevereiro, maio,agosto, novembro
A40: INDUSTRIAL | B40: SP (Naturgy) | C40: com pis/cofins e sem icms | D40: 7 | E40: SP | F40: NATURGY | G40: Industrial | H40: =I39+0.01 -> 5000000 | I40: 10000000 | J40: 2.7653 | K40: 210708.77 | L40: 46173 | M40: 0.09 | N40: =_xlfn.XLOOKUP(E40,ICMS!C:C,ICMS!D:D) -> 0.15 | O40: =1+O39 -> 39 | Q40: Não | R40: https://www.naturgy.com.br/atendimento/tarifas/tarifa_sao_paulo | S40: fevereiro, maio,agosto, novembro
...

Sheet Calculo impostos
B2: com pis/cofins de 9% | C2: 2.8763
B3: sem pis/cofins de 9% | C3: =C2*(1-9/100) -> 2.617433 | D3: =Tarifario!#REF!*(1-8.9/100) -> #REF!
B4: com pis/cofins de 9% e icms de 15% | C4: =C3/(1-9/100)/(1-15/100) -> 3.3838824 | D4: =Tarifario!#REF!/(1-8.9/100)/(1-15/100) -> #REF!
B5: sem pis/cofins de 9% e icms de 15% | C5: =C4*(1-9/100)*(1-15/100) -> 2.617433

Sheet uf sem GN
A1: UF | B1: Tem GN?
A2: AC | B2: Nao
A3: AP | B3: Nao
A4: DF | B4: Nao
A5: GO | B5: Nao
A6: MA | B6: Nao
A7: PA | B7: Nao
A8: PI | B8: Nao
A9: RO | B9: Nao
A10: RR | B10: Nao
A11: TO | B11: Nao
A13: =COUNTA(A2:A11) -> 10

Sheet ICMS
B2: Regiao | C2: UF | D2: ICMS | E2: tem GN
B3: CO | C3: DF | E3: =_xlfn.XLOOKUP(C3,'uf sem GN'!A:A,'uf sem GN'!B:B,"Sim") -> Nao
B4: CO | C4: GO | E4: =_xlfn.XLOOKUP(C4,'uf sem GN'!A:A,'uf sem GN'!B:B,"Sim") -> Nao
B5: N | C5: AC | E5: =_xlfn.XLOOKUP(C5,'uf sem GN'!A:A,'uf sem GN'!B:B,"Sim") -> Nao
B6: N | C6: AP | E6: =_xlfn.XLOOKUP(C6,'uf sem GN'!A:A,'uf sem GN'!B:B,"Sim") -> Nao
B7: N | C7: PA | E7: =_xlfn.XLOOKUP(C7,'uf sem GN'!A:A,'uf sem GN'!B:B,"Sim") -> Nao
B8: N | C8: RO | E8: =_xlfn.XLOOKUP(C8,'uf sem GN'!A:A,'uf sem GN'!B:B,"Sim") -> Nao
B9: N | C9: RR | E9: =_xlfn.XLOOKUP(C9,'uf sem GN'!A:A,'uf sem GN'!B:B,"Sim") -> Nao
B10: N | C10: TO | E10: =_xlfn.XLOOKUP(C10,'uf sem GN'!A:A,'uf sem GN'!B:B,"Sim") -> Nao
B11: NE | C11: MA | E11: =_xlfn.XLOOKUP(C11,'uf sem GN'!A:A,'uf sem GN'!B:B,"Sim") -> Nao
B12: NE | C12: PI | E12: =_xlfn.XLOOKUP(C12,'uf sem GN'!A:A,'uf sem GN'!B:B,"Sim") -> Nao
B13: CO | C13: MT | D13: 0.17 | E13: =_xlfn.XLOOKUP(C13,'uf sem GN'!A:A,'uf sem GN'!B:B,"Sim") -> Sim
B14: CO | C14: MS | D14: 0.17 | E14: =_xlfn.XLOOKUP(C14,'uf sem GN'!A:A,'uf sem GN'!B:B,"Sim") -> Sim
B15: N | C15: AM | D15: 0.2 | E15: =_xlfn.XLOOKUP(C15,'uf sem GN'!A:A,'uf sem GN'!B:B,"Sim") -> Sim
B16: NE | C16: AL | D16: 0.2 | E16: =_xlfn.XLOOKUP(C16,'uf sem GN'!A:A,'uf sem GN'!B:B,"Sim") -> Sim
B17: NE | C17: BA | D17: 0.12 | E17: =_xlfn.XLOOKUP(C17,'uf sem GN'!A:A,'uf sem GN'!B:B,"Sim") -> Sim
B18: NE | C18: CE | D18: 0.2 | E18: =_xlfn.XLOOKUP(C18,'uf sem GN'!A:A,'uf sem GN'!B:B,"Sim") -> Sim
B19: NE | C19: PB | D19: 0.2 | E19: =_xlfn.XLOOKUP(C19,'uf sem GN'!A:A,'uf sem GN'!B:B,"Sim") -> Sim
B20: NE | C20: PE | D20: 0.205 | E20: =_xlfn.XLOOKUP(C20,'uf sem GN'!A:A,'uf sem GN'!B:B,"Sim") -> Sim
B21: NE | C21: RN | D21: 0.2 | E21: =_xlfn.XLOOKUP(C21,'uf sem GN'!A:A,'uf sem GN'!B:B,"Sim") -> Sim
B22: NE | C22: SE | D22: 0.2 | E22: =_xlfn.XLOOKUP(C22,'uf sem GN'!A:A,'uf sem GN'!B:B,"Sim") -> Sim
B23: S | C23: PR | D23: 0.12 | E23: =_xlfn.XLOOKUP(C23,'uf sem GN'!A:A,'uf sem GN'!B:B,"Sim") -> Sim
B24: S | C24: RS | D24: 0.12 | E24: =_xlfn.XLOOKUP(C24,'uf sem GN'!A:A,'uf sem GN'!B:B,"Sim") -> Sim
... B29: SE | C29: SP | D29: 0.15 | E29: =_xlfn.XLOOKUP(C29,'uf sem GN'!A:A,'uf sem GN'!B:B,"Sim") -> Sim

Sheet Observações
B2: Naturgy SP | C2: Faixa media Condominio estimada VQ
B3: PB | C3: Semana para mês (*4,345)
C5: Algumas tarifas estao publicadas por dia ou semana
C6: Há estados com incentivos fiscais

Sheet conversa_com_o_tributario
C2: industria pode creditar 1,47 a cada kg de glp | D2: Simples não
C3: Industria pode creditar 9,25% de PIS/COFINS sobre o faturado da nota | D3: Lucro Real
C5: Tem haver com a aplicação
C10: Nota | D10: valor unit | E10: Valor total
C11: 60kg glp | D11: 7 | E11: =D11*60 -> 420
C14: Uso no processo industrial, pode creditar creditos GN e GLP
C15: exceto o Industrial não credita
C17: Regime de trbutação
C18: Uso do GLP do cliente
C20: pf não credita
C21: pj com inscricão estatual pode creditar
C22: em 01/01/2027 morre pis/cofins
C23: icms 2029 gradativo

Sheet Cliente_teste_metrica
B2: Cliente_teste | D2: kg glp | E2: preço por kg glp | F2: m3 GN | G2: preço por m3 GN | H2: preço equivalente gn kg glp
B3: 11642 | D3: 11642 | E3: 6.73 | F3: =D3*1.25 -> 14552.5 | G3: 3.01 | H3: =G3*1.25 -> 3.7625
C4: fatura | E4: =D3*E3 -> 78350.66 | G4: =F3*G3 -> 43803.025 | H4: =D3*H3 -> 43803.025
H7: =E3-H3 -> 2.9675
